
  0%|                                                                                                                                     | 0/115 [00:00<?, ?it/s]
epoch_idx: 0
  0%|                                                                                                                                     | 0/115 [00:03<?, ?it/s]
Traceback (most recent call last):
  File "/home-nfs/fx2024/NLP/NLP/main.py", line 340, in <module>
    gpt_finetune(args, model)
  File "/home-nfs/fx2024/NLP/NLP/main.py", line 138, in gpt_finetune
    loss = model(batch_input_ids, attention_mask=batch_attention_mask, labels=batch_input_ids).loss.sum()
           ^^^^^^^^^^^^^^^^^^^^^^^^^^^^^^^^^^^^^^^^^^^^^^^^^^^^^^^^^^^^^^^^^^^^^^^^^^^^^^^^^^^
  File "/home-nfs/fx2024/mc3/envs/fei-venv/lib/python3.11/site-packages/torch/nn/modules/module.py", line 1511, in _wrapped_call_impl
    return self._call_impl(*args, **kwargs)
           ^^^^^^^^^^^^^^^^^^^^^^^^^^^^^^^^
  File "/home-nfs/fx2024/mc3/envs/fei-venv/lib/python3.11/site-packages/torch/nn/modules/module.py", line 1520, in _call_impl
    return forward_call(*args, **kwargs)
           ^^^^^^^^^^^^^^^^^^^^^^^^^^^^^
  File "/home-nfs/fx2024/mc3/envs/fei-venv/lib/python3.11/site-packages/torch/nn/parallel/data_parallel.py", line 185, in forward
    outputs = self.parallel_apply(replicas, inputs, module_kwargs)
              ^^^^^^^^^^^^^^^^^^^^^^^^^^^^^^^^^^^^^^^^^^^^^^^^^^^^
  File "/home-nfs/fx2024/mc3/envs/fei-venv/lib/python3.11/site-packages/torch/nn/parallel/data_parallel.py", line 200, in parallel_apply
    return parallel_apply(replicas, inputs, kwargs, self.device_ids[:len(replicas)])
           ^^^^^^^^^^^^^^^^^^^^^^^^^^^^^^^^^^^^^^^^^^^^^^^^^^^^^^^^^^^^^^^^^^^^^^^^^
  File "/home-nfs/fx2024/mc3/envs/fei-venv/lib/python3.11/site-packages/torch/nn/parallel/parallel_apply.py", line 108, in parallel_apply
    output.reraise()
  File "/home-nfs/fx2024/mc3/envs/fei-venv/lib/python3.11/site-packages/torch/_utils.py", line 722, in reraise
    raise exception
torch.cuda.OutOfMemoryError: Caught OutOfMemoryError in replica 0 on device 0.
Original Traceback (most recent call last):
  File "/home-nfs/fx2024/mc3/envs/fei-venv/lib/python3.11/site-packages/torch/nn/parallel/parallel_apply.py", line 83, in _worker
    output = module(*input, **kwargs)
             ^^^^^^^^^^^^^^^^^^^^^^^^
  File "/home-nfs/fx2024/mc3/envs/fei-venv/lib/python3.11/site-packages/torch/nn/modules/module.py", line 1511, in _wrapped_call_impl
    return self._call_impl(*args, **kwargs)
           ^^^^^^^^^^^^^^^^^^^^^^^^^^^^^^^^
  File "/home-nfs/fx2024/mc3/envs/fei-venv/lib/python3.11/site-packages/torch/nn/modules/module.py", line 1520, in _call_impl
    return forward_call(*args, **kwargs)
           ^^^^^^^^^^^^^^^^^^^^^^^^^^^^^
  File "/home-nfs/fx2024/mc3/envs/fei-venv/lib/python3.11/site-packages/transformers/models/gpt2/modeling_gpt2.py", line 1105, in forward
    shift_logits = lm_logits[..., :-1, :].contiguous()
                   ^^^^^^^^^^^^^^^^^^^^^^^^^^^^^^^^^^^
torch.cuda.OutOfMemoryError: CUDA out of memory. Tried to allocate 1.53 GiB. GPU 0 has a total capacity of 47.54 GiB of which 357.81 MiB is free. Process 225567 has 2.67 GiB memory in use. Process 229622 has 802.00 MiB memory in use. Process 239697 has 26.99 GiB memory in use. Process 239962 has 862.00 MiB memory in use. Including non-PyTorch memory, this process has 15.89 GiB memory in use. Of the allocated memory 15.35 GiB is allocated by PyTorch, and 109.68 MiB is reserved by PyTorch but unallocated. If reserved but unallocated memory is large try setting PYTORCH_CUDA_ALLOC_CONF=expandable_segments:True to avoid fragmentation.  See documentation for Memory Management  (https://pytorch.org/docs/stable/notes/cuda.html#environment-variables)