2024-02-12 20:41:10,878 INFO    StreamThr :30304 [internal.py:wandb_internal():86] W&B internal server running at pid: 30304, started at: 2024-02-12 20:41:10.876951
2024-02-12 20:41:10,881 DEBUG   HandlerThread:30304 [handler.py:handle_request():146] handle_request: status
2024-02-12 20:41:10,887 INFO    WriterThread:30304 [datastore.py:open_for_write():87] open: /home-nfs/fx2024/NLP/NLP/wandb/run-20240212_204110-test/run-test.wandb
2024-02-12 20:41:10,888 DEBUG   SenderThread:30304 [sender.py:send():382] send: header
2024-02-12 20:41:10,902 DEBUG   SenderThread:30304 [sender.py:send():382] send: run
2024-02-12 20:41:10,908 INFO    SenderThread:30304 [sender.py:_maybe_setup_resume():763] checking resume status for None/test-project/test
2024-02-12 20:41:11,130 ERROR   SenderThread:30304 [internal_api.py:execute():373] 409 response executing GraphQL.
2024-02-12 20:41:11,130 ERROR   SenderThread:30304 [internal_api.py:execute():374] {"errors":[{"message":"run fayxu/test-project/test was previously created and deleted; try a new run name","path":["upsertBucket"]}],"data":{"upsertBucket":null}}
2024-02-12 20:41:12,338 ERROR   SenderThread:30304 [internal_api.py:execute():373] 409 response executing GraphQL.
2024-02-12 20:41:12,338 ERROR   SenderThread:30304 [internal_api.py:execute():374] {"errors":[{"message":"run fayxu/test-project/test was previously created and deleted; try a new run name","path":["upsertBucket"]}],"data":{"upsertBucket":null}}
2024-02-12 20:41:14,454 ERROR   SenderThread:30304 [internal_api.py:execute():373] 409 response executing GraphQL.
2024-02-12 20:41:14,455 ERROR   SenderThread:30304 [internal_api.py:execute():374] {"errors":[{"message":"run fayxu/test-project/test was previously created and deleted; try a new run name","path":["upsertBucket"]}],"data":{"upsertBucket":null}}
2024-02-12 20:41:14,455 INFO    SenderThread:30304 [retry.py:__call__():172] Retry attempt failed:
Traceback (most recent call last):
  File "/home-nfs/fx2024/mc3/envs/fei-venv/lib/python3.11/site-packages/wandb/sdk/lib/retry.py", line 131, in __call__
    result = self._call_fn(*args, **kwargs)
             ^^^^^^^^^^^^^^^^^^^^^^^^^^^^^^
  File "/home-nfs/fx2024/mc3/envs/fei-venv/lib/python3.11/site-packages/wandb/sdk/internal/internal_api.py", line 369, in execute
    return self.client.execute(*args, **kwargs)  # type: ignore
           ^^^^^^^^^^^^^^^^^^^^^^^^^^^^^^^^^^^^
  File "/home-nfs/fx2024/mc3/envs/fei-venv/lib/python3.11/site-packages/wandb/vendor/gql-0.2.0/wandb_gql/client.py", line 52, in execute
    result = self._get_result(document, *args, **kwargs)
             ^^^^^^^^^^^^^^^^^^^^^^^^^^^^^^^^^^^^^^^^^^^
  File "/home-nfs/fx2024/mc3/envs/fei-venv/lib/python3.11/site-packages/wandb/vendor/gql-0.2.0/wandb_gql/client.py", line 60, in _get_result
    return self.transport.execute(document, *args, **kwargs)
           ^^^^^^^^^^^^^^^^^^^^^^^^^^^^^^^^^^^^^^^^^^^^^^^^^
  File "/home-nfs/fx2024/mc3/envs/fei-venv/lib/python3.11/site-packages/wandb/sdk/lib/gql_request.py", line 59, in execute
    request.raise_for_status()
  File "/home-nfs/fx2024/mc3/envs/fei-venv/lib/python3.11/site-packages/requests/models.py", line 1021, in raise_for_status
    raise HTTPError(http_error_msg, response=self)
requests.exceptions.HTTPError: 409 Client Error: Conflict for url: https://api.wandb.ai/graphql
2024-02-12 20:41:15,904 DEBUG   HandlerThread:30304 [handler.py:handle_request():146] handle_request: keepalive
2024-02-12 20:41:18,940 ERROR   SenderThread:30304 [internal_api.py:execute():373] 409 response executing GraphQL.
2024-02-12 20:41:18,941 ERROR   SenderThread:30304 [internal_api.py:execute():374] {"errors":[{"message":"run fayxu/test-project/test was previously created and deleted; try a new run name","path":["upsertBucket"]}],"data":{"upsertBucket":null}}
2024-02-12 20:41:20,905 DEBUG   HandlerThread:30304 [handler.py:handle_request():146] handle_request: keepalive
2024-02-12 20:41:25,907 DEBUG   HandlerThread:30304 [handler.py:handle_request():146] handle_request: keepalive
2024-02-12 20:41:27,220 ERROR   SenderThread:30304 [internal_api.py:execute():373] 409 response executing GraphQL.
2024-02-12 20:41:27,221 ERROR   SenderThread:30304 [internal_api.py:execute():374] {"errors":[{"message":"run fayxu/test-project/test was previously created and deleted; try a new run name","path":["upsertBucket"]}],"data":{"upsertBucket":null}}
2024-02-12 20:41:30,908 DEBUG   HandlerThread:30304 [handler.py:handle_request():146] handle_request: keepalive
2024-02-12 20:41:35,909 DEBUG   HandlerThread:30304 [handler.py:handle_request():146] handle_request: keepalive
2024-02-12 20:41:37,298 DEBUG   HandlerThread:30304 [handler.py:handle_request():146] handle_request: shutdown
2024-02-12 20:41:37,298 INFO    HandlerThread:30304 [handler.py:finish():869] shutting down handler
2024-02-12 20:41:37,907 INFO    WriterThread:30304 [datastore.py:close():296] close: /home-nfs/fx2024/NLP/NLP/wandb/run-20240212_204110-test/run-test.wandb
2024-02-12 20:41:44,527 ERROR   SenderThread:30304 [internal_api.py:execute():373] 409 response executing GraphQL.
2024-02-12 20:41:44,527 ERROR   SenderThread:30304 [internal_api.py:execute():374] {"errors":[{"message":"run fayxu/test-project/test was previously created and deleted; try a new run name","path":["upsertBucket"]}],"data":{"upsertBucket":null}}
2024-02-12 20:42:22,770 ERROR   SenderThread:30304 [internal_api.py:execute():373] 409 response executing GraphQL.
2024-02-12 20:42:22,770 ERROR   SenderThread:30304 [internal_api.py:execute():374] {"errors":[{"message":"run fayxu/test-project/test was previously created and deleted; try a new run name","path":["upsertBucket"]}],"data":{"upsertBucket":null}}
2024-02-12 20:43:27,957 ERROR   SenderThread:30304 [internal_api.py:execute():373] 409 response executing GraphQL.
2024-02-12 20:43:27,958 ERROR   SenderThread:30304 [internal_api.py:execute():374] {"errors":[{"message":"run fayxu/test-project/test was previously created and deleted; try a new run name","path":["upsertBucket"]}],"data":{"upsertBucket":null}}
2024-02-12 20:43:27,958 ERROR   SenderThread:30304 [sender.py:send_run():987] run fayxu/test-project/test was previously created and deleted; try a new run name (Error 409: Conflict)
Traceback (most recent call last):
  File "/home-nfs/fx2024/mc3/envs/fei-venv/lib/python3.11/site-packages/wandb/apis/normalize.py", line 41, in wrapper
    return func(*args, **kwargs)
           ^^^^^^^^^^^^^^^^^^^^^
  File "/home-nfs/fx2024/mc3/envs/fei-venv/lib/python3.11/site-packages/wandb/sdk/internal/internal_api.py", line 2216, in upsert_run
    response = self.gql(
               ^^^^^^^^^
  File "/home-nfs/fx2024/mc3/envs/fei-venv/lib/python3.11/site-packages/wandb/sdk/internal/internal_api.py", line 341, in gql
    ret = self._retry_gql(
          ^^^^^^^^^^^^^^^^
  File "/home-nfs/fx2024/mc3/envs/fei-venv/lib/python3.11/site-packages/wandb/sdk/lib/retry.py", line 131, in __call__
    result = self._call_fn(*args, **kwargs)
             ^^^^^^^^^^^^^^^^^^^^^^^^^^^^^^
  File "/home-nfs/fx2024/mc3/envs/fei-venv/lib/python3.11/site-packages/wandb/sdk/internal/internal_api.py", line 369, in execute
    return self.client.execute(*args, **kwargs)  # type: ignore
           ^^^^^^^^^^^^^^^^^^^^^^^^^^^^^^^^^^^^
  File "/home-nfs/fx2024/mc3/envs/fei-venv/lib/python3.11/site-packages/wandb/vendor/gql-0.2.0/wandb_gql/client.py", line 52, in execute
    result = self._get_result(document, *args, **kwargs)
             ^^^^^^^^^^^^^^^^^^^^^^^^^^^^^^^^^^^^^^^^^^^
  File "/home-nfs/fx2024/mc3/envs/fei-venv/lib/python3.11/site-packages/wandb/vendor/gql-0.2.0/wandb_gql/client.py", line 60, in _get_result
    return self.transport.execute(document, *args, **kwargs)
           ^^^^^^^^^^^^^^^^^^^^^^^^^^^^^^^^^^^^^^^^^^^^^^^^^
  File "/home-nfs/fx2024/mc3/envs/fei-venv/lib/python3.11/site-packages/wandb/sdk/lib/gql_request.py", line 59, in execute
    request.raise_for_status()
  File "/home-nfs/fx2024/mc3/envs/fei-venv/lib/python3.11/site-packages/requests/models.py", line 1021, in raise_for_status
    raise HTTPError(http_error_msg, response=self)
requests.exceptions.HTTPError: 409 Client Error: Conflict for url: https://api.wandb.ai/graphql

During handling of the above exception, another exception occurred:

Traceback (most recent call last):
  File "/home-nfs/fx2024/mc3/envs/fei-venv/lib/python3.11/site-packages/wandb/sdk/internal/sender.py", line 985, in send_run
    self._init_run(run, config_value_dict)
  File "/home-nfs/fx2024/mc3/envs/fei-venv/lib/python3.11/site-packages/wandb/sdk/internal/sender.py", line 1027, in _init_run
    server_run, inserted, server_messages = self._api.upsert_run(
                                            ^^^^^^^^^^^^^^^^^^^^^
  File "/home-nfs/fx2024/mc3/envs/fei-venv/lib/python3.11/site-packages/wandb/apis/normalize.py", line 51, in wrapper
    raise CommError(message, error)
wandb.errors.CommError: run fayxu/test-project/test was previously created and deleted; try a new run name (Error 409: Conflict)
2024-02-12 20:43:27,965 INFO    SenderThread:30304 [sender.py:finish():1572] shutting down sender
